Workbook

Sheet kyrell's project board - ai-age
A1: Kyrell's Project Board - AI-agentic SOC triage engine
A2: Week 1- Project Foundation & Planning
A3: Name | B3: Subitems | C3: Person | D3: Status | E3: Date | F3: Checkbox | G3: Item ID (auto generated)
A4: Project Setup & Development Environment | C4: Kyrell Green | D4: Done | E4: 46251 | F4: v | G4: 12726202658
A5: Design the Alert Schema | C5: Kyrell Green | D5: Done | G5: 12726300556
A6: Learn FastAPI Fundamentals | C6: Kyrell Green | D6: Done | G6: 12726350604
A7: Build the Identity API Skeleton | C7: Kyrell Green | D7: Done | G7: 12726389663
A8: TEST/Debug | D8: Working on it | G8: 12737974625
A9: Status Update | D9: Done | E9: 46254 | F9: v | G9: 12856971058
E10: 2026-08-17 to 2026-08-20 | F10: 2/6
A12: Week 2- Building the identity source
A13: Name | B13: Subitems | C13: Person | D13: Status | E13: Date | F13: Checkbox | G13: Item ID (auto generated)
A14: Learn Pydantic Models | C14: Kyrell Green | D14: Done | E14: 46258 | G14: 12726484445
A15: Generate Synthetic Identity Data | C15: Kyrell Green | D15: Done | E15: 46259 | G15: 12726437133
A16: Connect FastAPI to PostgreSQL | C16: Kyrell Green | D16: N/A | E16: 46260 | G16: 12726460552
A17: Attack Scenario Generator | C17: Kyrell Green | D17: Done | E17: 46261 | G17: 12726485623
A18: TEST/Debug | D18: Working on it | G18: 12737960971
E19: 2026-08-24 to 2026-08-27 | F19: 0/5
A21: Week 3- SIEM mock service -> "Wazuh Integration"
A22: Name | B22: Subitems | C22: Person | D22: Status | E22: Date | F22: Checkbox | G22: Item ID (auto generated)
A23: Design the SIEM Event Schema | C23: Kyrell Green | D23: Done | E23: 46265 | G23: 12715429015
A24: Build the SIEM FastAPI Service | C24: Kyrell Green | D24: Done | E24: 46266 | G24: 12715428090
A25: Generate SIEM Attack Events | C25: Kyrell Green | D25: Done | E25: 46267 | G25: 12715481534
A26: Integration Testing & Project Review | C26: Kyrell Green | D26: Done | E26: 46268 | G26: 12715398467
A27: TEST/Debug | C27: Kyrell Green | G27: 12737980224
E28: 2026-08-31 to 2026-09-03 | F28: 0/5
A30: Week 4- Build the EDR Mock Service
A31: Name | B31: Subitems | C31: Person | D31: Status | E31: Date | F31: Checkbox | G31: Item ID (auto generated)
A32: Design the EDR Data Model | C32: Kyrell Green | D32: Done | E32: 46272 | G32: 12715482241
A33: Generate Synthetic Endpoint Telemetry | C33: Kyrell Green | D33: Done | E33: 46273 | G33: 12715484072
A34: Build the EDR FastAPI Service | C34: Kyrell Green | D34: Done | E34: 46274 | G34: 12715483928
A35: End-to-End API Integration | C35: Kyrell Green | D35: Done | E35: 46275 | G35: 12715481949
A36: Weekly Goal | G36: 12726641813
A37: Monthly Presentation | E37: 46275 | F37: v | G37: 13019911458
E38: 2026-09-07 to 2026-09-10 | F38: 1/6
A40: WEEK 5- Learn LangGraph & Build the Supervisor
A41: Name | B41: Subitems | C41: Person | D41: Status | E41: Date | F41: Checkbox | G41: Item ID (auto generated)
A42: Learn LangGraph Fundamentals | C42: Kyrell Green | D42: Done | E42: 46279 | G42: 12726676250
A43: Create the Investigation State | C43: Kyrell Green | D43: Done | E43: 46280 | G43: 12726699225
A44: Build the Supervisor Node | C44: Kyrell Green | D44: Done | E44: 46281 | G44: 12726690477
...

Sheet Rubric Summary
A1: Rubric coverage summary
A2: All counts are formulas over 'Rubric Checklist' and 'Board Additions'; change a Status there and this sheet updates.
A3: Environment note: the IR rubric names Parrot OS + VirtualBox + macOS; your lab is Kali + UTM + Dockerized Wazuh on a Mac. Confirm the substitution with your instructor (board subitem on Oct 12).
A5: Partial credit weight | B5: 0.5 | C5: Assumption: a 'Partial' row counts as half done in % complete (my choice; edit to taste).
A7: Rubric | B7: Crit. | C7: Criterion | D7: Requirements | E7: Done | F7: Partial | G7: Not started | H7: % complete | I7: Board subitems linked
A8: Security Monitoring | B8: M1 | C8: Monitoring Environment Setup | D8: =COUNTIF('Rubric Checklist'!$C$5:$C$50,$B8) -> 5 | E8: =COUNTIFS('Rubric Checklist'!$C$5:$C$50,$B8,'Rubric Checklist'!$I$5:$I$50,"Done") -> 2 | F8: =COUNTIFS('Rubric Checklist'!$C$5:$C$50,$B8,'Rubric Checklist'!$I$5:$I$50,"Partial") -> 3 | G8: =COUNTIFS('Rubric Checklist'!$C$5:$C$50,$B8,'Rubric Checklist'!$I$5:$I$50,"Not started") -> 0 | H8: =IF(D8=0,0,(E8+$B$5*F8)/D8) -> 0.7 | I8: =COUNTIF('Board Additions'!$G$5:$G$22,"*"&$B8&".*") -> 3
A9: Security Monitoring | B9: M2 | C9: Security Event Analysis | D9: =COUNTIF('Rubric Checklist'!$C$5:$C$50,$B9) -> 5 | E9: =COUNTIFS('Rubric Checklist'!$C$5:$C$50,$B9,'Rubric Checklist'!$I$5:$I$50,"Done") -> 4 | F9: =COUNTIFS('Rubric Checklist'!$C$5:$C$50,$B9,'Rubric Checklist'!$I$5:$I$50,"Partial") -> 1 | G9: =COUNTIFS('Rubric Checklist'!$C$5:$C$50,$B9,'Rubric Checklist'!$I$5:$I$50,"Not started") -> 0 | H9: =IF(D9=0,0,(E9+$B$5*F9)/D9) -> 0.9 | I9: =COUNTIF('Board Additions'!$G$5:$G$22,"*"&$B9&".*") -> 0
A10: Security Monitoring | B10: M3 | C10: Monitoring Implementation | D10: =COUNTIF('Rubric Checklist'!$C$5:$C$50,$B10) -> 5 | E10: =COUNTIFS('Rubric Checklist'!$C$5:$C$50,$B10,'Rubric Checklist'!$I$5:$I$50,"Done") -> 2 | F10: =COUNTIFS('Rubric Checklist'!$C$5:$C$50,$B10,'Rubric Checklist'!$I$5:$I$50,"Partial") -> 1 | G10: =COUNTIFS('Rubric Checklist'!$C$5:$C$50,$B10,'Rubric Checklist'!$I$5:$I$50,"Not started") -> 2 | H10: =IF(D10=0,0,(E10+$B$5*F10)/D10) -> 0.5 | I10: =COUNTIF('Board Additions'!$G$5:$G$22,"*"&$B10&".*") -> 2
A11: Security Monitoring | B11: M4 | C11: Security Reporting | D11: =COUNTIF('Rubric Checklist'!$C$5:$C$50,$B11) -> 5 | E11: =COUNTIFS('Rubric Checklist'!$C$5:$C$50,$B11,'Rubric Checklist'!$I$5:$I$50,"Done") -> 0 | F11: =COUNTIFS('Rubric Checklist'!$C$5:$C$50,$B11,'Rubric Checklist'!$I$5:$I$50,"Partial") -> 5 | G11: =COUNTIFS('Rubric Checklist'!$C$5:$C$50,$B11,'Rubric Checklist'!$I$5:$I$50,"Not started") -> 0 | H11: =IF(D11=0,0,(E11+$B$5*F11)/D11) -> 0.5 | I11: =COUNTIF('Board Additions'!$G$5:$G$22,"*"&$B11&".*") -> 4
A12: Incident Response | B12: I1 | C12: IR Environment Setup | D12: =COUNTIF('Rubric Checklist'!$C$5:$C$50,$B12) -> 6 | E12: =COUNTIFS('Rubric Checklist'!$C$5:$C$50,$B12,'Rubric Checklist'!$I$5:$I$50,"Done") -> 1 | F12: =COUNTIFS('Rubric Checklist'!$C$5:$C$50,$B12,'Rubric Checklist'!$I$5:$I$50,"Partial") -> 4 | G12: =COUNTIFS('Rubric Checklist'!$C$5:$C$50,$B12,'Rubric Checklist'!$I$5:$I$50,"Not started") -> 1 | H12: =IF(D12=0,0,(E12+$B$5*F12)/D12) -> 0.5 | I12: =COUNTIF('Board Additions'!$G$5:$G$22,"*"&$B12&".*") -> 4
A13: Incident Response | B13: I2 | C13: Incident Detection and Analysis | D13: =COUNTIF('Rubric Checklist'!$C$5:$C$50,$B13) -> 4 | E13: =COUNTIFS('Rubric Checklist'!$C$5:$C$50,$B13,'Rubric Checklist'!$I$5:$I$50,"Done") -> 1 | F13: =COUNTIFS('Rubric Checklist'!$C$5:$C$50,$B13,'Rubric Checklist'!$I$5:$I$50,"Partial") -> 3 | G13: =COUNTIFS('Rubric Checklist'!$C$5:$C$50,$B13,'Rubric Checklist'!$I$5:$I$50,"Not started") -> 0 | H13: =IF(D13=0,0,(E13+$B$5*F13)/D13) -> 0.625 | I13: =COUNTIF('Board Additions'!$G$5:$G$22,"*"&$B13&".*") -> 3
A14: Incident Response | B14: I3 | C14: Incident Response and Containment | D14: =COUNTIF('Rubric Checklist'!$C$5:$C$50,$B14) -> 3 | E14: =COUNTIFS('Rubric Checklist'!$C$5:$C$50,$B14,'Rubric Checklist'!$I$5:$I$50,"Done") -> 0 | F14: =COUNTIFS('Rubric Checklist'!$C$5:$C$50,$B14,'Rubric Checklist'!$I$5:$I$50,"Partial") -> 3 | G14: =COUNTIFS('Rubric Checklist'!$C$5:$C$50,$B14,'Rubric Checklist'!$I$5:$I$50,"Not started") -> 0 | H14: =IF(D14=0,0,(E14+$B$5*F14)/D14) -> 0.5 | I14: =COUNTIF('Board Additions'!$G$5:$G$22,"*"&$B14&".*") -> 3
A15: Incident Response | B15: I4 | C15: Digital Evidence Management | D15: =COUNTIF('Rubric Checklist'!$C$5:$C$50,$B15) -> 5 | E15: =COUNTIFS('Rubric Checklist'!$C$5:$C$50,$B15,'Rubric Checklist'!$I$5:$I$50,"Done") -> 0 | F15: =COUNTIFS('Rubric Checklist'!$C$5:$C$50,$B15,'Rubric Checklist'!$I$5:$I$50,"Partial") -> 2 | G15: =COUNTIFS('Rubric Checklist'!$C$5:$C$50,$B15,'Rubric Checklist'!$I$5:$I$50,"Not started") -> 3 | H15: =IF(D15=0,0,(E15+$B$5*F15)/D15) -> 0.2 | I15: =COUNTIF('Board Additions'!$G$5:$G$22,"*"&$B15&".*") -> 3
A16: Incident Response | B16: I5 | C16: IR Documentation and Reporting | D16: =COUNTIF('Rubric Checklist'!$C$5:$C$50,$B16) -> 4 | E16: =COUNTIFS('Rubric Checklist'!$C$5:$C$50,$B16,'Rubric Checklist'!$I$5:$I$50,"Done") -> 2 | F16: =COUNTIFS('Rubric Checklist'!$C$5:$C$50,$B16,'Rubric Checklist'!$I$5:$I$50,"Partial") -> 2 | G16: =COUNTIFS('Rubric Checklist'!$C$5:$C$50,$B16,'Rubric Checklist'!$I$5:$I$50,"Not started") -> 0 | H16: =IF(D16=0,0,(E16+$B$5*F16)/D16) -> 0.75 | I16: =COUNTIF('Board Additions'!$G$5:$G$22,"*"&$B16&".*") -> 2
A17: Incident Response | B17: I6 | C17: Post-Incident Procedures | D17: =COUNTIF('Rubric Checklist'!$C$5:$C$50,$B17) -> 4 | E17: =COUNTIFS('Rubric Checklist'!$C$5:$C$50,$B17,'Rubric Checklist'!$I$5:$I$50,"Done") -> 2 | F17: =COUNTIFS('Rubric Checklist'!$C$5:$C$50,$B17,'Rubric Checklist'!$I$5:$I$50,"Partial") -> 1 | G17: =COUNTIFS('Rubric Checklist'!$C$5:$C$50,$B17,'Rubric Checklist'!$I$5:$I$50,"Not started") -> 1 | H17: =IF(D17=0,0,(E17+$B$5*F17)/D17) -> 0.625 | I17: =COUNTIF('Board Additions'!$G$5:$G$22,"*"&$B17&".*") -> 1
A19: Security Monitoring | D19: =SUMIF($A$8:$A$17,$A19,D$8:D$17) -> 20 | E19: =SUMIF($A$8:$A$17,$A19,E$8:E$17) -> 8 | F19: =SUMIF($A$8:$A$17,$A19,F$8:F$17) -> 10 | G19: =SUMIF($A$8:$A$17,$A19,G$8:G$17) -> 2 | H19: =IF(D19=0,0,(E19+$B$5*F19)/D19) -> 0.65 | I19: =SUMIF($A$8:$A$17,$A19,I$8:I$17) -> 9
A20: Incident Response | D20: =SUMIF($A$8:$A$17,$A20,D$8:D$17) -> 26 | E20: =SUMIF($A$8:$A$17,$A20,E$8:E$17) -> 6 | F20: =SUMIF($A$8:$A$17,$A20,F$8:F$17) -> 15 | G20: =SUMIF($A$8:$A$17,$A20,G$8:G$17) -> 5 | H20: =IF(D20=0,0,(E20+$B$5*F20)/D20) -> 0.51923077 | I20: =SUMIF($A$8:$A$17,$A20,I$8:I$17) -> 16
A21: Overall | D21: =SUM(D8:D17) -> 46 | E21: =SUM(E8:E17) -> 14 | F21: =SUM(F8:F17) -> 25 | G21: =SUM(G8:G17) -> 7 | H21: =IF(D21=0,0,(E21+$B$5*F21)/D21) -> 0.57608696 | I21: =SUM(I8:I17) -> 25

Sheet Rubric Checklist
A1: Rubric checklist: Security Monitoring + Incident Response
A2: Edit only the Status column (dropdown) and add links in 'Existing evidence' as you capture them. Status reflects the repo as of Oct 12, 2026 plus your Oct 5-8 notes; re-check anything marked Done before submitting.
A3: Target date = earliest linked subitem on 'Board Additions' (assumption: set by me from the board's week windows).
A4: ID | B4: Rubric | C4: Crit. | D4: Criterion | E4: Requirement | F4: Board tie-in | G4: Existing evidence | H4: Gap / next action | I4: Status | J4: Target date
A5: M1.1 | B5: Security Monitoring | C5: M1 | D5: Monitoring Environment Setup | E5: Wazuh (or similar) installed and configured, with evidence of network configuration | F5: Week 3 - Wazuh Integration | G5: Wazuh 4.14.7 Docker stack; ARCHITECTURE.md; SIEM_Implementation.md; Network_Topology report (10.11.0.0/22) | H5: Add a 'docker compose ps' screenshot and one dashboard screenshot | I5: Done
A6: M1.2 | B6: Security Monitoring | C6: M1 | D6: Monitoring Environment Setup | E6: Log collection from 2+ source types (Windows and Linux) with verified connectivity | F6: Week 3 / AGENT_DEPLOYMENT_STATUS | G6: Agent 002 Kali (Linux) and agent 007 DESKTOP-VCKJCPV (Windows, enrolled 2026-09-23); Ping.png; test_wazuh_connection.py | H6: Screenshot of Agents page showing both Active | I6: Done
A7: M1.3 | B7: Security Monitoring | C7: M1 | D7: Monitoring Environment Setup | E7: Alert rules for 3+ scenarios (authentication, file access, network activity) | F7: Week 3; Week 9 adds | G7: Auth: stock 5763/40112 plus custom 100002/100003. Windows: custom 100010/100011. Network: custom 100020/100021 (Suricata). File access: stock FIM rule 550 | H7: Show rules in local_rules.xml + logtest proof; confirm Suricata alerts reach Wazuh; fix ID 100010 meaning in older docs | I7: Partial | J7: 46309
A8: M1.4 | B8: Security Monitoring | C8: M1 | D8: Monitoring Environment Setup | E8: Basic monitoring workflow showing alert routing and notification configuration | F8: Week 9 - Approval Gate | G8: SOC_Operations.md workflow (alert to TheHive to analyst). Live ossec.conf had email_notification = no and no Wazuh-to-TheHive connector as of Oct 5 | H8: Configure one real path (email or TheHive integration) and capture a test alert | I8: Partial | J8: 46308
A9: M1.5 | B9: Security Monitoring | C9: M1 | D9: Monitoring Environment Setup | E9: Screenshots: dashboard, configuration files, log collection, rule triggering | F9: Week 9 | G9: 5 screenshots in ai-agentic-soc/screenshots (agent deployment, agents list, ping, test server, Aug 19 dashboard) | H9: Missing: ossec.conf, local_rules.xml, a rule-trigger (5763/40112) view | I9: Partial | J9: 46309
A10: M2.1 | B10: Security Monitoring | C10: M2 | D10: Security Event Analysis | E10: Analysis of 3+ log types with clear interpretation methodology | F10: Week 7 - Correlation | G10: Threat_Detection_Principles.md: sshd auth, FIM, Windows event channel, SCA, vulnerability detector | H10: None | I10: Done
A11: M2.2 | B11: Security Monitoring | C11: M2 | D11: Security Event Analysis | E11: Correlation between 2+ log sources showing related events | F11: Week 7 - Correlation Engine | G11: Auth log (passwd labtester, rule 5402) + FIM /etc/shadow change (rule 550); evidence gatherer joins Wazuh + identity + EDR | H11: Label the two sources explicitly as a correlation exercise. Do not use the Suricata replay (synthetic 2002 timestamps) as a correlation source | I11: Done
A12: M2.3 | B12: Security Monitoring | C12: M2 | D12: Security Event Analysis | E12: Complete incident detection scenario: timeline, correlation, conclusions | F12: Week 8 - First End-to-End Investigation | G12: SOC-CASE-2026-0142 (rule 40112 level 12, 71 ms session, no post-access activity) | H12: None | I12: Done
A13: M2.4 | B13: Security Monitoring | C13: M2 | D13: Security Event Analysis | E13: Alert triage process: severity assessment, false-positive identification, escalation criteria | F13: Week 9 - Approval Workflow | G13: Incident_Response_Template A.9 severity matrix; Methodology escalation triggers D1-D7; benign examples (rootcheck 510, DCOM 61110) | H13: Put the false-positive examples in a table inside the repo docs | I13: Partial
A14: M2.5 | B14: Security Monitoring | C14: M2 | D14: Security Event Analysis | E14: Annotated log excerpts, interpretation of findings, investigation methodology | F14: Week 8 - Logging | G14: Methodology sec. 6 and 8 (verbatim full_log lines, queries to re-derive) | H14: None | I14: Done
A15: M3.1 | B15: Security Monitoring | C15: M3 | D15: Monitoring Implementation | E15: Monitoring architecture diagram with components and data flows | F15: Week 3 | G15: Mermaid diagrams in SIEM_Implementation sec. 1.2 and Monitor_and_Respond sec. 1.1 | H15: Export one combined image including TheHive, Suricata and the triage engine | I15: Done
A16: M3.2 | B16: Security Monitoring | C16: M3 | D16: Monitoring Implementation | E16: 3+ data sources integrated with evidence of successful collection | F16: Week 3-4 | G16: Linux auth/journald, Windows event channel, FIM, SCA, vulnerability detector; indexer queries in Methodology sec. 8 | H16: Screenshot of each source in Discover | I16: Done
A17: M3.3 | B17: Security Monitoring | C17: M3 | D17: Monitoring Implementation | E17: Performance baselines for normal operations with defined alert thresholds | F17: Week 10 | G17: Wazuh rule 11 fired on 2026-10-01 ('average 561, reached 1812') - an existing baseline signal | H17: Build baseline table from indexer (alerts/day per agent, failed logins per source) and state thresholds | I17: Not started | J17: 46315
A18: M3.4 | B18: Security Monitoring | C18: M3 | D18: Monitoring Implementation | E18: Health monitoring: collection status, processing performance, storage utilization | F18: Week 10 | G18: IndexerClient.ping(); /agents status; /manager/status; known Docker VM RAM limit (7.7 GiB) | H18: Write health_check.py and document the procedure | I18: Not started | J18: 46315
A19: M3.5 | B19: Security Monitoring | C19: M3 | D19: Monitoring Implementation | E19: Implementation docs: config files, integration steps, baselines, health check procedures | F19: Week 11 - Technical Documentation | G19: README.md; SIEM_Implementation.md; ARCHITECTURE.md | H19: Baselines and health procedures missing (see M3.3, M3.4) | I19: Partial
A20: M4.1 | B20: Security Monitoring | C20: M4 | D20: Security Reporting | E20: Standardized alert documentation template used for 3+ alert types | F20: Testing and Evaluation | G20: Incident_Response_Template.md (Sections A-J); 1 completed instance (0142) | H20: Complete 2 more types (e.g. vulnerability CVE, SCA score, Windows account change) | I20: Partial | J20: 46321
A21: M4.2 | B21: Security Monitoring | C21: M4 | D21: Security Reporting | E21: Security metrics: operational, coverage, effectiveness, with measurement methods | F21: Testing - Measure Performance | G21: 0142: declared about 2 min, D3 under 1 min, contained T+20. Board task already plans accuracy / FP / FN | H21: Consolidate into one metrics table with a method per metric | I21: Partial | J21: 46323
A22: M4.3 | B22: Security Monitoring | C22: M4 | D22: Security Reporting | E22: Security summary report: alert trends, significant findings, recommendations | F22: Documentation week | G22: Findings I.1-I.9 in the IR report; weekly status updates | H22: Add alert-trend section from indexer counts | I22: Partial | J22: 46330
A23: M4.4 | B23: Security Monitoring | C23: M4 | D23: Security Reporting | E23: At least one dashboard showing real-time security status with visualizations | F23: Week 10 - SOC Dashboard | G23: Wazuh dashboard is live; Streamlit alert queue planned Oct 19-22 | H23: Decide which dashboard you submit; add health panel | I23: Partial | J23: 46316
A24: M4.5 | B24: Security Monitoring | C24: M4 | D24: Security Reporting | E24: Professional standards: organization, appropriate detail, actionable information | F24: All documentation | G24: Consistent rubric-coverage tables and doc maps across reports | H24: Final proofread pass | I24: Partial
A25: I1.1 | B25: Incident Response | C25: I1 | D25: IR Environment Setup | E25: Wazuh SIEM on Parrot OS (VirtualBox) with agent deployment | F25: Week 3 | G25: Wazuh on Docker (Mac) + Kali agent in UTM (Parrot/VirtualBox not used) | H25: ENVIRONMENT MISMATCH: get instructor sign-off that Kali/UTM substitutes | I25: Partial | J25: 46307
A26: I1.2 | B26: Incident Response | C26: I1 | D26: IR Environment Setup | E26: Log collection configuration from Parrot OS | F26: Week 3 | G26: Kali agent 002 shipping auth/journald events; Firewall_IDS_IPS report localfile config | H26: None beyond naming Kali instead of Parrot | I26: Done
A27: I1.3 | B27: Incident Response | C27: I1 | D27: IR Environment Setup | E27: Creation of 3 custom alert rules for security events | F27: Week 9 | G27: Custom rules 100002/100003, 100010/100011, 100020/100021 written Oct 5-8 | H27: Capture local_rules.xml + logtest; fix doc rule-ID conflicts | I27: Partial | J27: 46309
A28: I1.4 | B28: Incident Response | C28: I1 | D28: IR Environment Setup | E28: Wireshark configured with proper capture filters | F28: Testing week | G28: Network_Security_Tools_Report sec. 1 (filter: host 10.11.3.57 and tcp port 22) | H28: That section was drafted - run a real capture and screenshot it | I28: Partial
A29: I1.5 | B29: Incident Response | C29: I1 | D29: IR Environment Setup | E29: Volatility framework with memory analysis configuration | F29: Testing week (stretch) | G29: None | H29: Install Volatility 3 on Kali, document config | I29: Not started | J29: 46324
A30: I1.6 | B30: Incident Response | C30: I1 | D30: IR Environment Setup | E30: System logging from both Parrot OS and macOS ingested into Wazuh | F30: Week 10 | G30: Kali ingestion works | H30: No macOS agent: enroll the Mac and show events in the dashboard | I30: Partial | J30: 46314
A31: I2.1 | B31: Incident Response | C31: I2 | D31: Incident Detection and Analysis | E31: Analysis of both Parrot OS and macOS logs in Wazuh with methodology | F31: Week 10 / Testing | G31: Kali analysis complete (Methodology) | H31: Add macOS analysis after I1.6 | I31: Partial | J31: 46314
A32: I2.2 | B32: Incident Response | C32: I2 | D32: Incident Detection and Analysis | E32: Investigation of 1 suspicious login: host-to-Parrot log correlation, timeline, alert validation | F32: Week 8 | G32: SOC-CASE-2026-0142; note source IP 192.168.64.3 is Kali's own address (self-generated test) | H32: Add host-side (macOS) log correlation to the timeline | I32: Partial | J32: 46321
A33: I2.3 | B33: Incident Response | C33: I2 | D33: Incident Detection and Analysis | E33: Classification of 3 distinct incidents using the taught severity matrix | F33: Testing week | G33: 1 classified (0142 = High). Candidates ready: 2026-09-30 blocked run, CIS SCA 19005 (score 27%), Windows 4738 events, GIMP CVEs | H33: Write and classify 2 more | I33: Partial | J33: 46321
A34: I2.4 | B34: Incident Response | C34: I2 | D34: Incident Detection and Analysis | E34: Documented methodologies and potential security implications | F34: Week 7-8 | G34: Threat_Detection_Principles.md; Methodology sec. 5 | H34: None | I34: Done
A35: I3.1 | B35: Incident Response | C35: I3 | D35: Incident Response and Containment | E35: Network isolation: interface configuration, firewall rules, segmentation via VM networking | F35: Week 9 | G35: Firewall_IDS_IPS report (ufw rules); Network_Topology (LAN segmentation) | H35: Demonstrate interface down + UTM network-mode change with screenshots | I35: Partial | J35: 46307
A36: I3.2 | B36: Incident Response | C36: I3 | D36: Incident Response and Containment | E36: Evidence preservation: file system artifacts, network captures, memory dumps | F36: Testing week | G36: pcap replay via run_ids.sh; alert records quoted verbatim | H36: No file-system artifact collection or memory dump yet | I36: Partial | J36: 46322
A37: I3.3 | B37: Incident Response | C37: I3 | D37: Incident Response and Containment | E37: Containment playbook: host isolation, traffic blocking, service shutdown | F37: Week 9 - Approval Workflow | G37: Methodology and IR Plan describe containment decisions (source block, isolation declined with reason) | H37: Standalone playbook with commands | I37: Partial | J37: 46307
A38: I4.1 | B38: Incident Response | C38: I4 | D38: Digital Evidence Management | E38: Live data collection: system state, processes, network connections | F38: Testing week | G38: None | H38: Run and save ps/ss/lsof-style output on Kali | I38: Not started | J38: 46322
A39: I4.2 | B39: Incident Response | C39: I4 | D39: Digital Evidence Management | E39: Basic memory analysis with Volatility, performed and documented | F39: Testing week (stretch) | G39: None | H39: Capture memory, run Volatility, document | I39: Not started | J39: 46324
A40: I4.3 | B40: Incident Response | C40: I4 | D40: Digital Evidence Management | E40: Disk acquisition with imaging tools and proper procedures | F40: Testing week (stretch) | G40: None | H40: Image a VM disk, record hash | I40: Not started | J40: 46324
...

Sheet Board Additions
A1: Board additions: subitems that fold the rubrics into the existing weeks
A2: Add each row as a Subitem under the named parent on the Monday board (Status blank = not started, same as the existing board). Rubric IDs refer to the 'Rubric Checklist' sheet.
A4: Parent item (existing) | B4: Parent date | C4: New subitem (Name) | D4: Person | E4: Status | F4: Date | G4: Rubric IDs | H4: Deliverable / evidence to produce
A5: Design the Approval Workflow | B5: 46307 | C5: Confirm with instructor that Kali (UTM) + Dockerized Wazuh on the Mac substitutes for Parrot OS (VirtualBox) | D5: Kyrell Green | F5: 46307 | G5: I1.1 | H5: Written confirmation (email/Slack) saved with the project docs
A6: Design the Approval Workflow | B6: 46307 | C6: Write the containment playbook for Kali: isolate interface, block IPs, stop services, with an approval tier per action | D6: Kyrell Green | F6: 46307 | G6: I3.3, I3.1 | H6: Playbook .md with exact commands + screenshots of interface down and UTM network-mode change
A7: Implement the Approval Gate | B7: 46308 | C7: Configure alert routing + notification (Wazuh to TheHive, or email) and capture a test alert arriving | D7: Kyrell Green | F7: 46308 | G7: M1.4 | H7: ossec.conf excerpt + screenshot of the alert landing in TheHive/inbox
A8: Build the Analyst Console (CLI Version) | B8: 46309 | C8: Capture proof for custom rules 100002-100021: local_rules.xml, logtest output, dashboard hit | D8: Kyrell Green | F8: 46309 | G8: M1.3, M1.5, I1.3 | H8: 3 screenshots per scenario (auth, Windows process/file, network)
A9: Adversarial Testing | B9: 46310 | C9: Reconcile docs with live config (SIEM_Implementation sec. 2 and 4.1; rule ID 100010 now used differently) | D9: Kyrell Green | F9: 46310 | G9: M1.3, M1.4 | H9: Corrected SIEM_Implementation.md that matches the running manager
A10: Learn Streamlit Fundamentals | B10: 46314 | C10: Enroll the macOS host as a Wazuh agent and confirm log ingestion | D10: Kyrell Green | F10: 46314 | G10: I1.6, I2.1 | H10: Agents page showing Kali, Windows 007 and macOS Active + a macOS event in Discover
A11: Build the Alert Queue | B11: 46315 | C11: Write scripts/health_check.py (agent status, indexer cluster health, manager status, disk/RAM) and define alert baselines + thresholds | D11: Kyrell Green | F11: 46315 | G11: M3.3, M3.4 | H11: health_check.py output + baseline table (alerts/day per agent, failed logins per source)
A12: Display Investigation Results | B12: 46316 | C12: Add a health + metrics panel to the Streamlit dashboard (real-time security status) | D12: Kyrell Green | F12: 46316 | G12: M4.4, M3.4 | H12: Dashboard screenshot
A13: Implement Approval Buttons | B13: 46317 | C13: Write approve/reject decisions to the TheHive case timeline (incident tracking evidence) | D13: Kyrell Green | F13: 46317 | G13: I5.2 | H13: TheHive case showing the analyst decision with timestamp
A14: Generate the Test Dataset | B14: 46321 | C14: Re-run Hydra with the macOS agent live; correlate macOS + Kali events into one timeline | D14: Kyrell Green | F14: 46321 | G14: I2.2, I4.5, I2.1 | H14: Combined timeline table + annotated log excerpts
A15: Generate the Test Dataset | B15: 46321 | C15: Complete 2 more incident cases with Incident_Response_Template (e.g. CVE rule 23504, SCA 19005, Windows event 4738) and classify all 3 with the severity matrix | D15: Kyrell Green | F15: 46321 | G15: M4.1, I2.3 | H15: 2 new case files + a 3-row severity classification table
A16: Run Full System Evaluation | B16: 46322 | C16: Live data collection on Kali (processes, connections, system state), pcap, file hashes, chain-of-custody form | D16: Kyrell Green | F16: 46322 | G16: I4.1, I3.2, I4.4 | H16: Saved command output, SHA-256 list, signed custody form
... A22: Final QA & Project Release | B22: 46331 | C22: Sign-off: every row on Rubric Checklist is Done and has an evidence link | D22: Kyrell Green | F22: 46331 | G22: All | H22: Rubric Summary shows 100%

Sheet updates
A1: Kyrell's Project Board - AI-agentic SOC triage engine | B1: Updates
A2: Item ID | B2: Item Name | C2: Content Type | D2: Content Type | E2: User | F2: Created At | G2: Update Content | H2: Likes Count | I2: Asset IDs | J2: Post ID | K2: Parent Post ID
A3: 12715428090 | B3: Build the SIEM FastAPI Service | C3: Update | E3: Kyrell Green | F3: 05/August/2026 04:32:28 PM | G3: Description ----------- Create a second FastAPI application that serves SIEM events. Implement endpoints to retrieve alerts, search historical events, and filter by user, host, or severity. Example endpoints: GET /events GET /events/user/{username} GET /events/host/{hostname} GET /events/severity/{level} Deliverable * Working SIEM API * Database integration * Search functionality | H3: 0 | J3: 5435262661
A4: 12715429015 | B4: Design the SIEM Event Schema | C4: Update | E4: Kyrell Green | F4: 05/August/2026 04:30:32 PM | G4: Description ----------- Study the structure of SIEM events and define your own simplified event format. Include timestamps, hostnames, usernames, event IDs, event types, severity, MITRE ATT&CK references, and descriptions. Populate PostgreSQL with baseline events. Deliverable * SIEM event schema * Event database * Baseline event dataset | H4: 0 | J4: 5435254530
A5: 12715398467 | B5: Integration Testing & Project Review | C5: Update | E5: Kyrell Green | F5: 05/August/2026 04:35:12 PM | G5: Description ----------- Test everything built during the first three weeks. Verify that PostgreSQL stores data correctly, the Identity API returns expected results, and the SIEM API can query historical events. Clean up project folders, remove unused code, update the README, and commit a stable milestone version. Deliverable * Identity API complete * SIEM API complete * PostgreSQL populated * Stable project milestone * Updated documentation | H5: 0 | J5: 5435272317
A6: 12715481534 | B6: Generate SIEM Attack Events | C6: Update | E6: Kyrell Green | F6: 05/August/2026 04:33:35 PM | G6: Description ----------- Extend your synthetic data generator to create realistic security events that correspond to your four attack scenarios. Ensure events appear in chronological order and can later be correlated with identity and endpoint information. Deliverable * Historical SIEM events * Attack-related logs * Correlated event timeline | H6: 0 | J6: 5435266490
A7: 12715482241 | B7: Design the EDR Data Model | C7: Update | E7: Kyrell Green | F7: 05/August/2026 04:38:19 PM | G7: Description ----------- Study what endpoint detection platforms monitor. Design your own simplified endpoint telemetry schema. Each endpoint should have: * Hostname * Username * Operating System * Running Processes * Network Connections * Parent/Child Processes * File Activity * Risk Score Create PostgreSQL tables to store endpoint activity. Deliverables * PostgreSQL EDR tables * Endpoint schema * Initial documentation | H7: 0 | J7: 5435289131
A8: 12715483928 | B8: Build the EDR FastAPI Service | C8: Update | E8: Kyrell Green | F8: 05/August/2026 04:40:43 PM | G8: Description ----------- Create the third FastAPI application. Example endpoints: GET /devices GET /devices/{hostname} GET /devices/{hostname}/processes GET /devices/{hostname}/connections Return PostgreSQL data instead of placeholder JSON. Deliverables * Working EDR API * PostgreSQL integration * API documentation | H8: 0 | J8: 5435298816
A9: 12715481949 | B9: End-to-End API Integration | C9: Update | E9: Kyrell Green | F9: 05/August/2026 04:41:57 PM | G9: Description ----------- Run all three APIs simultaneously. Verify: Identity API ↓ SIEM API ↓ EDR API Confirm each API returns valid JSON. Test every endpoint using Swagger. Fix bugs. Organize folders. Commit milestone. Deliverables Identity API SIEM API EDR API PostgreSQL connected | H9: 0 | J9: 5435302737
A10: 12715484072 | B10: Generate Synthetic Endpoint Telemetry | C10: Update | E10: Kyrell Green | F10: 05/August/2026 04:39:03 PM | G10: Description ----------- Create Python scripts that generate realistic endpoint activity. Examples: * Chrome launches * Outlook launches * PowerShell execution * CMD execution * Network connections * File downloads * USB insertions Inject suspicious behavior for your four attack scenarios. Deliverables * Endpoint dataset * Synthetic telemetry generator * Attack behaviors | H10: 0 | J10: 5435292972
A11: 12726202658 | B11: Project Setup & Development Environment | C11: Update | E11: Kyrell Green | F11: 05/August/2026 04:10:45 PM | G11: Description ----------- Set up the entire development environment from scratch. Create the Git repository, Python virtual environment, install all required packages, and initialize PostgreSQL. Create the project's folder structure (agent, APIs, database, frontend, docs, tests). Verify that PostgreSQL is running and that Python can successfully connect to it. Finish by making the first Git commit. Deliverable * Working virtual environment * PostgreSQL running * Project folder structure * Initial Git repository | H11: 0 | J11: 5435152996
A12: 12726202658 | B12: Project Setup & Development Environment | D12: Reply | E12: Kyrell Green | F12: 10/September/2026 04:54:14 PM | G12: The SIEM pillar is no longer a locally simulated Splunk/FastAPI mock. It is replaced by **the real Wazuh 4.14.7 single-node deployment already running in this project's SOC lab** (Docker, hosted on the development Mac). Wazuh is now **both** the alert source (where detections originate) **and** the historical evidence pillar (SIEM history queries). Alert ingestion switches from a hand-fed Splunk-ES-shaped JSON file to live pulls file to live pulls from the Wazuh API. | H12: 0 | J12: 5537043117 | K12: 5435152996
A13: 12726300556 | B13: Design the Alert Schema | C13: Update | E13: Kyrell Green | F13: 05/August/2026 04:11:39 PM | G13: Description ----------- Study how SOC alerts are structured and design the JSON format your project will accept. Define fields such as alert ID, timestamp, username, hostname, source IP, destination IP, severity, alert type, and description. Create several sample alert JSON files that will be used throughout the project. Deliverable * Final alert JSON schema * Five sample alerts * JSON validation completed | H13: 0 | J13: 5435156387
A14: 12726350604 | B14: Learn FastAPI Fundamentals | C14: Update | E14: Kyrell Green | F14: 05/August/2026 04:17:19 PM | G14: Description ----------- Install FastAPI and Uvicorn. Build your first API application, create GET endpoints, understand decorators, automatic documentation, and JSON responses. Learn how to test endpoints using the built-in Swagger interface. Deliverable * First FastAPI application * Three working endpoints * Swagger documentation accessible | H14: 0 | J14: 5435185307
A15: 12726389663 | B15: Build the Identity API Skeleton | C15: Update | E15: Kyrell Green | F15: 05/August/2026 04:21:31 PM | G15: Description ----------- Create the Identity microservice. Define the API routes you expect the AI agent to use later, such as retrieving a user profile, login history, and MFA status. Use placeholder data for now to verify the API structure. Example endpoints: GET /users/{username} GET /users/{username}/logins GET /users/{username}/mfa Deliverable * Identity API running * Three working endpoints * Placeholder responses | H15: 0 | J15: 5435201449
A16: 12726389663 | B16: Build the Identity API Skeleton | D16: Reply | E16: Kyrell Green | F16: 10/September/2026 04:02:39 PM | G16: Instead of building everything entirely from scratch, Wazuh is being utilized with simple login, note admin privileges are required via a DAE staff member. | H16: 0 | I16: 3239653441 | J16: 5536829367 | K16: 5435201449
A17: 12726484445 | B17: Learn Pydantic Models | C17: Update | E17: Kyrell Green | F17: 05/August/2026 04:24:57 PM | G17: Description ----------- Learn how FastAPI uses Pydantic for validation. Create models for users, login events, MFA settings, and user privileges. Understand request validation and response models. Deliverable * User model * Login model * MFA model * Validation working | H17: 0 | J17: 5435222482
A18: 12726437133 | B18: Generate Synthetic Identity Data | C18: Update | E18: Kyrell Green | F18: 05/August/2026 04:26:11 PM | G18: Description ----------- Create Python scripts that generate realistic user accounts. Each user should include usernames, departments, managers, privilege levels, login history, MFA settings, and locations. Save this data in PostgreSQL. Deliverable * 50–100 synthetic users * Database populated * Data generation script | H18: 0 | J18: 5435226641
A19: 12726460552 | B19: Connect FastAPI to PostgreSQL | C19: Update | E19: Kyrell Green | F19: 05/August/2026 04:27:10 PM | G19: Description ----------- Replace placeholder responses with live database queries. Learn SQLAlchemy (or another PostgreSQL library you choose) to retrieve user information from PostgreSQL. Verify all Identity API endpoints return real data. Deliverable * Database connection * Live API queries * Identity API fully connected | H19: 0 | J19: 5435231027
A20: 12726460552 | B20: Connect FastAPI to PostgreSQL | D20: Reply | E20: Kyrell Green | F20: 14/September/2026 04:20:37 PM | G20: Not necessarily needed for the minimum value product/project | H20: 0 | J20: 5545656198 | K20: 5435231027
A21: 12726485623 | B21: Attack Scenario Generator | C21: Update | E21: Kyrell Green | F21: 05/August/2026 04:27:57 PM | G21: Description ----------- Write functions that inject realistic attack behaviors into user accounts. Implement four scenarios: * Credential stuffing * Brute-force attack * Phishing compromise * Ransomware precursor Each scenario should modify login history and account activity so the AI agent has something meaningful to investigate later. Deliverable * Four attack generators * Realistic synthetic attack data | H21: 0 | J21: 5435235192
A22: 12726641813 | B22: Weekly Goal | C22: Update | E22: Kyrell Green | F22: 05/August/2026 04:43:31 PM | G22: Finish the last mock service (EDR). By the end of this week you'll have three complete backend services that simulate a real SOC environment. | H22: 0 | J22: 5435307848
A23: 12726676250 | B23: Learn LangGraph Fundamentals | C23: Update | E23: Kyrell Green | F23: 05/August/2026 04:48:36 PM | G23: Description ----------- Install: * LangChain * LangGraph Learn: * Nodes * Edges * State * Tool calling * Workflow execution Create a simple graph that prints: Start ↓ Investigate ↓ Finish Don't connect any APIs yet. Deliverables * First LangGraph workflow * Working StateGraph | H23: 0 | J23: 5435325620
A24: 12726676250 | B24: Learn LangGraph Fundamentals | C24: Update | E24: Abhinav Piratla | F24: 14/September/2026 04:01:51 PM | H24: 0 | I24: 3246262773, 3246262800 | J24: 5545568935
A25: 12726676250 | B25: Learn LangGraph Fundamentals | D25: Reply | E25: Abhinav Piratla | F25: 14/September/2026 04:02:04 PM | G25: @Kyrell Green Let me know if you cannot access it | H25: 1 | J25: 5545569842 | K25: 5545568935
A26: 12726699225 | B26: Create the Investigation State | C26: Update | E26: Kyrell Green | F26: 05/August/2026 04:50:39 PM | G26: Description ----------- Design the information that moves through the graph. Example state: alert identity_context siem_context edr_context timeline report recommendation Create your first TypedDict (or Pydantic model) for graph state. Deliverables * Investigation State * Graph schema | H26: 0 | J26: 5435333588
A27: 12726690477 | B27: Build the Supervisor Node | C27: Update | E27: Kyrell Green | F27: 05/August/2026 04:52:11 PM | G27: Description ----------- Create the AI supervisor. Its only job: Receive an alert ↓ Determine "What information do I need?" For now the supervisor only returns a list. Example: Investigate Identity Investigate SIEM Investigate EDR No tool calling yet. Deliverables * Supervisor node * Investigation planning | H27: 0 | J27: 5435339485
A28: 12726726941 | B28: Build the First Tool | C28: Update | E28: Kyrell Green | F28: 05/August/2026 04:53:39 PM | G28: Description ----------- Connect the Identity API. The supervisor now actually requests identity information. Flow: Alert ↓ Supervisor ↓ Identity API ↓ Receive response ↓ Print result Deliverables * First LangGraph tool * Identity lookup working | H28: 0 | J28: 5435344411
A29: 12726794813 | B29: Weekly Goal | C29: Update | E29: Kyrell Green | F29: 05/August/2026 04:55:26 PM | G29: Introduce AI into the project. This week you're learning LangGraph while keeping the workflow simple. | H29: 0 | J29: 5435350399
A30: 12726794813 | B30: Weekly Goal | D30: Reply | E30: Kyrell Green | F30: 16/September/2026 06:31:01 PM | G30: Implementing course rubric to fit into the project, Security Operations Center1: Prepare SOC Operations Documentation, Document SIEM Implementation, Document Threat Detection Principles, Document Incident Response Methodology. Cybersecurity Basics1: Create an Incident Response Plan, Develop a Comprehensive Security Policy, Apply Encryption Techniques, Demonstrate Legal and Ethical Compliance. | H30: 0 | J30: 5553664637 | K30: 5435350399
A31: 12726786427 | B31: Connect the SIEM Tool | C31: Update | E31: Kyrell Green | F31: 05/August/2026 04:56:20 PM | G31: Description ----------- Create another LangGraph tool. The supervisor should now call the SIEM API. Retrieve: * Historical alerts * Failed logins * User activity * Host activity Deliverables * SIEM tool connected | H31: 0 | J31: 5435353545
A32: 12726761012 | B32: Connect the EDR Tool | C32: Update | E32: Kyrell Green | F32: 05/August/2026 04:59:20 PM | G32: Description ----------- Create the third tool. Retrieve endpoint telemetry. Examples: Running processes Network connections Suspicious activity Now your graph should gather information from: Identity * SIEM * EDR Deliverables * EDR tool * Three tools connected | H32: 0 | J32: 5435364790
A33: 12726834681 | B33: Build the Investigation Timeline | C33: Update | E33: Kyrell Green | F33: 05/August/2026 05:01:12 PM | G33: Description ----------- Take the outputs from all three APIs. Merge them into a chronological timeline. Example: 08:00 Failed Login ↓ 08:05 VPN Login ↓ 08:07 PowerShell launched ↓ 08:10 Outbound Connection Don't worry about AI summaries yet. Focus only on chronology. Deliverables * Timeline builder * Unified investigation object | H33: 0 | J33: 5435372960
A34: 12726816232 | B34: Complete the First Automated Investigation | C34: Update | E34: Kyrell Green | F34: 05/August/2026 05:10:39 PM | G34: Description ----------- Run a complete alert. Example: Alert arrives ↓ Supervisor analyzes alert ↓ Calls Identity API ↓ Calls SIEM API ↓ Calls EDR API ↓ Creates timeline ↓ Print investigation This is the first time your project behaves like an investigation engine. Debug everything. Refactor messy code. Commit. Deliverables Three APIs connected LangGraph Supervisor Tool calling Automated investigation | H34: 0 | J34: 5435414995
A35: 12726841316 | B35: Weekly Goal | C35: Update | E35: Kyrell Green | F35: 05/August/2026 05:03:37 PM | G35: Turn the workflow into an actual investigation. | H35: 0 | J35: 5435382769
A36: 12727548441 | B36: Weekly Summary | C36: Update | E36: Kyrell Green | F36: 05/August/2026 05:59:51 PM | G36: Transform raw evidence into a coherent security investigation by correlating data from all three sources and mapping it to MITRE ATT&CK techniques. | H36: 0 | J36: 5435667996
A37: 12727557582 | B37: Design the Investigation Correlation Engine | C37: Update | E37: Kyrell Green | F37: 05/August/2026 06:00:48 PM | G37: Description ----------- Right now, your Identity API, SIEM API, and EDR API each return separate pieces of information. Your goal today is to design a single Python object that combines them into one investigation. Create a unified structure that contains: * Original alert * Identity findings * SIEM findings * EDR findings * Timeline events * Risk indicators Think of this as the "case file" that every later step will use. Deliverables * Investigation data model * Unified case object * Documentation of investigation flow | H37: 0 | J37: 5435672399
A38: 12727525999 | B38: Build the Correlation Engine | C38: Update | E38: Kyrell Green | F38: 05/August/2026 06:01:59 PM | G38: Description ----------- Write Python logic that merges findings from the three APIs. Example: Alert: Impossible Travel ↓ Identity: 12 failed logins ↓ SIEM: VPN login from Germany ↓ EDR: PowerShell executed ↓ One Investigation Your goal is not AI reasoning yet—just combining related evidence. Deliverables * Correlation function * Merged investigation * Single investigation object | H38: 0 | J38: 5435680040
A39: 12727577701 | B39: Implement MITRE ATT&CK Mapping | C39: Update | E39: Kyrell Green | F39: 05/August/2026 06:03:40 PM | G39: Description ----------- Create a simple rule-based mapping system. For example: Credential Stuffing ↓ Credential Access ↓ T1110 Another example: PowerShell ↓ Execution ↓ T1059 Start with only the techniques needed for your four attack scenarios. Do not try to implement the entire ATT&CK framework. Deliverables * ATT&CK lookup table * Rule-based mapper * Technique tags | H39: 0 | J39: 5435685997
A40: 12727597585 | B40: Validate All Attack Scenarios | C40: Update | E40: Kyrell Green | F40: 05/August/2026 06:04:44 PM | G40: Description ----------- Run all four attack scenarios. Verify: * Timeline is correct * Correlation works * ATT&CK mapping is accurate * No duplicate events appear Fix any inconsistencies. Commit milestone. Deliverables Four scenarios working ATT&CK mapped Correlation complete | H40: 0 | J40: 5435689801
...
